Workbook

Sheet Ke hoach
A1: VĂN PHÒNG ĐÀO TẠO QUỐC TẾ
A2: KẾ HOẠCH GIẢNG DẠY CHƯƠNG TRÌNH CỬ NHÂN CHẤT LƯỢNG CAO TĂNG CƯỜNG TIẾNG NHẬT KHÓA 2020
A4: Ngành: Khoa học Máy tính (Computer Science)
A5: Tổng số tín chỉ: | D5: 125
A6: STT | B6: MSMH | C6: Tên môn học | D6: Tín chỉ | E6: Tên môn học tiếng Anh
A7: Học kỳ 1 | D7: 16
A8: Các môn bắt buộc
A9: 1 | B9: LA1003 | C9: Anh văn 1 | D9: 2 | E9: English 1
A10: 2 | B10: PE1003 | C10: Giáo dục thể chất 1 | D10: 0 | E10: Physical Education 1
A11: 3 | B11: MT1003 | C11: Giải tích 1 | D11: 4 | E11: Calculus 1
A12: 4 | B12: PH1003 | C12: Vật lý 1 | D12: 4 | E12: General Physics 1
A13: 5 | B13: CO1005 | C13: Nhập môn điện toán | D13: 3 | E13: Introduction to Computing
A14: 6 | B14: CO1023 | C14: Hệ thống số | D14: 3 | E14: Digital Systems
A15: 7 | B15: LA1045 | C15: Tiếng Nhật 1 | D15: 0 | E15: Japanese 1
A16: 8 | B16: SP1041 | C16: Kỹ năng mềm | D16: 0 | E16: Soft Skill
A17: Các môn tự chọn nhóm kỹ năng xã hội (chọn 1 môn trong các môn học sau)
A18: 9 | B18: SP1013 | C18: Kỹ năng xã hội A (báo chí) | D18: 0 | E18: Social Skills A
A19: 10 | B19: SP1015 | C19: Kỹ năng xã hội B (sân khấu) | D19: 0 | E19: Social Skills B
A20: 11 | B20: SP1017 | C20: Kỹ năng xã hội C (Thanh nhạc) | D20: 0 | E20: Social Skills C
A21: 12 | B21: SP1019 | C21: Kỹ năng xã hội D (Nhiếp ảnh) | D21: 0 | E21: Social Skills D
A22: 13 | B22: SP1021 | C22: Kỹ năng xã hội E (dẫn chương trình) | D22: 0 | E22: Social Skills E
A23: 14 | B23: SP1023 | C23: Kỹ năng xã hội F (nhảy hiện đại) | D23: 0 | E23: Social Skills F
A24: 15 | B24: SP1025 | C24: Kỹ năng xã hội G (nhảy đường phố) | D24: 0 | E24: Social Skills G
A25: 16 | B25: SP1027 | C25: Kỹ năng xã hội H (tư duy phản biện) | D25: 0 | E25: Social Skills H
A26: Học kỳ 2 | D26: 17
A27: Các môn bắt buộc
A28: 1 | B28: LA1005 | C28: Anh văn 2 | D28: 2 | E28: English 2
A29: 2 | B29: PE1005 | C29: Giáo dục thể chất 2 | D29: 0 | E29: Physical Education 2
A30: 3 | B30: MT1005 | C30: Giải tích 2 | D30: 4 | E30: Calculus 2
A31: 4 | B31: MT1007 | C31: Đại số tuyến tính | D31: 3 | E31: Linear Algebra
A32: 5 | B32: CO1007 | C32: Cấu trúc rời rạc cho khoa học máy tính | D32: 4 | E32: Discrete Structures for Computing
A33: 6 | B33: CO1027 | C33: Kỹ thuật lập trình | D33: 3 | E33: Programming Fundamentals
A34: 7 | B34: PH1007 | C34: Thí nghiệm vật lý | D34: 1 | E34: General Physics Labs
A35: 8 | B35: LA1047 | C35: Tiếng Nhật 2 | D35: 0 | E35: Japanese 2
A36: Học kỳ 3 | D36: 16
A37: Các môn bắt buộc
A38: 1 | B38: LA1007 | C38: Anh văn 3 | D38: 2 | E38: English 3
A39: 1 | B39: SP1031 | C39: Triết học Mác - Lênin | D39: 3 | E39: Marxist - Leninist Philosophy
A40: 2 | B40: CO2007 | C40: Kiến trúc máy tính | D40: 4 | E40: Computer Architecture
A41: 3 | B41: CO2011 | C41: Mô hình hóa toán học | D41: 3 | E41: Mathematical Modeling
...

Sheet CTDT
A1: Ngành: Khoa học Máy tính (Computer Science) - 128tc
A2: STT | B2: MSMH | C2: Tên môn học | D2: Tín chỉ | E2: MH-BB/TC | F2: Kế hoạch-HK | G2: Tính chất môn học
A3: 1 | B3: LA1003 | C3: Anh văn 1 | D3: 2 | E3: x | F3: 1 | G3: Kiến thức GD đại cương - Ngoại ngữ
A4: 2 | B4: PE1003 | C4: Giáo dục thể chất 1 | D4: 0 | E4: x | F4: 1 | G4: Chứng chỉ
A5: 3 | B5: MT1003 | C5: Giải tích 1 | D5: 4 | E5: x | F5: 1 | G5: Kiến thức GD đại cương - Toán
A6: 4 | B6: PH1003 | C6: Vật lý 1 | D6: 4 | E6: x | F6: 1 | G6: Kiến thức GD đại cương - Khoa học tự nhiên
A7: 5 | B7: CO1005 | C7: Nhập môn điện toán | D7: 3 | E7: x | F7: 1 | G7: Kiến thức GD đại cương - Giáo dục chung khác (Nhập môn)
A8: 6 | B8: CO1023 | C8: Hệ thống số | D8: 3 | E8: x | F8: 1 | G8: Kiến thức GD chuyên nghiệp - Cơ sở ngành
A9: 7 | B9: LA1045 | C9: Tiếng Nhật 1 | D9: 0 | E9: x | F9: 1 | G9: Kiến thức GD đại cương - Ngoại ngữ
A10: 8 | B10: SP1041 | C10: Kỹ năng mềm | D10: 0 | E10: x | F10: 1 | G10: Kỹ năng xã hội
A11: 9 | B11: SP1013 | C11: Kỹ năng xã hội A (báo chí) | D11: 0 | E11: TC-1 (1/8 môn) | F11: 1 | G11: Kỹ năng xã hội
A12: 10 | B12: SP1015 | C12: Kỹ năng xã hội B (sân khấu) | D12: 0 | E12: TC-1 (1/8 môn) | F12: 1 | G12: Kỹ năng xã hội
A13: 11 | B13: SP1017 | C13: Kỹ năng xã hội C (Thanh nhạc) | D13: 0 | E13: TC-1 (1/8 môn) | F13: 1 | G13: Kỹ năng xã hội
A14: 12 | B14: SP1019 | C14: Kỹ năng xã hội D (Nhiếp ảnh) | D14: 0 | E14: TC-1 (1/8 môn) | F14: 1 | G14: Kỹ năng xã hội
... A40: 38 | B40: LA2019 | C40: Tiếng Nhật 4 | D40: 0 | E40: x | F40: 4 | G40: Kiến thức GD đại cương - Ngoại ngữ
A41: 39 | C41: Tự chọn tự do (3/9tc) | D41: 3 | E41: TC-TD (9tc) | F41: 4 | G41: Tự chọn tự do
A42: 40 | B42: SP1035 | C42: Chủ nghĩa xã hội khoa học | D42: 2 | E42: x | F42: 5 | G42: Kiến thức GD đại cương - Kinh tế-Chính trị-Xã hội-Luật
A43: 41 | B43: CO3093 | C43: Mạng máy tính | D43: 3 | E43: x | F43: 5 | G43: Kiến thức GD chuyên nghiệp - Chuyên ngành
A44: 42 | B44: CO2013 | C44: Hệ cơ sở dữ liệu | D44: 4 | E44: x | F44: 5 | G44: Kiến thức GD chuyên nghiệp - Cơ sở ngành
A45: 43 | B45: CO3001 | C45: Công nghệ phần mềm | D45: 3 | E45: x | F45: 5 | G45: Kiến thức GD chuyên nghiệp - Chuyên ngành
A46: 44 | B46: CH1003 | C46: Hóa đại cương | D46: 3 | E46: x | F46: 5 | G46: Kiến thức GD đại cương - Khoa học tự nhiên
A47: 45 | B47: LA3025 | C47: Tiếng Nhật 5 | D47: 0 | E47: x | F47: 5 | G47: Kiến thức GD đại cương - Ngoại ngữ
A48: 46 | B48: SP1043 | C48: Văn hoá Nhật | D48: 0 | E48: x | F48: 5 | G48: Kỹ năng xã hội
A49: 47 | B49: CO3101 | C49: Đồ án tổng hợp - hướng trí tuệ nhân tạo | D49: 1 | E49: TC-2 (1tc) | F49: 5 | G49: Kiến thức GD chuyên nghiệp - Chuyên ngành (nhóm tự chọn A)
A50: 48 | B50: CO3103 | C50: Đồ án tổng hợp - hướng công nghệ phần mềm | D50: 1 | E50: TC-2 (1tc) | F50: 5 | G50: Kiến thức GD chuyên nghiệp - Chuyên ngành (nhóm tự chọn A)
A51: 49 | B51: CO3105 | C51: Đồ án tổng hợp - hướng hệ thống thông tin | D51: 1 | E51: TC-2 (1tc) | F51: 5 | G51: Kiến thức GD chuyên nghiệp - Chuyên ngành (nhóm tự chọn A)
A52: 50 | B52: SP1039 | C52: Lịch sử Đảng Cộng sản Việt Nam | D52: 2 | E52: x | F52: 6 | G52: Kiến thức GD đại cương - Kinh tế-Chính trị-Xã hội-Luật
A53: 51 | B53: CO3029 | C53: Khai phá dữ liệu | D53: 3 | E53: x | F53: 6
A54: 52 | B54: CO3089 | C54: Những chủ đề nâng cao trong khoa học máy tính | D54: 3 | E54: x | F54: 6
A55: 53 | B55: CO3061 | C55: Nhập môn trí tuệ nhân tạo | D55: 3 | E55: x | F55: 6
A56: 54 | B56: LA3027 | C56: Tiếng Nhật 6 | D56: 0 | E56: x | F56: 6 | G56: Kiến thức GD đại cương - Ngoại ngữ
A57: 55 | B57: CO3107 | C57: Thực tập đồ án môn học đa ngành - hướng trí tuệ nhân tạo | D57: 1 | E57: TC-3 (1tc) | F57: 6 | G57: Kiến thức GD chuyên nghiệp - Chuyên ngành (nhóm tự chọn B)
A58: 56 | B58: CO3109 | C58: Thực tập đồ án môn học đa ngành - hướng công nghệ phần mềm | D58: 1 | E58: TC-3 (1tc) | F58: 6 | G58: Kiến thức GD chuyên nghiệp - Chuyên ngành (nhóm tự chọn B)
A59: 57 | B59: CO3111 | C59: Thực tập đồ án môn học đa ngành - hướng hệ thống thông tin | D59: 1 | E59: TC-3 (1tc) | F59: 6 | G59: Kiến thức GD chuyên nghiệp - Chuyên ngành (nhóm tự chọn B)
A60: 58 | C60: Tự chọn tự do (3/9tc) | D60: 3 | E60: TC-TD (9tc) | F60: 6 | G60: Tự chọn tự do
A61: 59 | B61: CO3335 | C61: Thực tập ngoài trường | D61: 2 | E61: x | F61: 6-hè | G61: Tốt nghiệp
A62: 60 | B62: SP1037 | C62: Tư tưởng Hồ Chí Minh | D62: 2 | E62: x | F62: 7 | G62: Kiến thức GD đại cương - Kinh tế-Chính trị-Xã hội-Luật
A63: 61 | B63: CO4029 | C63: Đồ án chuyên ngành | D63: 2 | E63: x | F63: 7 | G63: Tốt nghiệp
A64: 62 | B64: CO2001 | C64: Kỹ năng chuyên nghiệp cho kỹ sư | D64: 3 | E64: x | F64: 7 | G64: Kiến thức GD đại cương - Giáo dục chung khác (Con người và môi trường)
A65: 63 | B65: CO3005 | C65: Nguyên lý ngôn ngữ lập trình | D65: 4 | E65: x | F65: 7 | G65: Kiến thức GD chuyên nghiệp - Chuyên ngành
...

Sheet KQ-hoctap
G1: điểm TBTL | H1: =SUM(H3:H39)/(SUM(D3:D39)-(0)) -> 1.2545455 | J1: =SUM(H4:H80)/SUM(I4:I80) -> 1.7692308 | L1: DM gia su | M1: =SUM(M4:M80)/SUM(N4:N80) -> 1.974359 | U1: Thang 10 | V1: Điểm chữ | W1: Điểm số | X1: Điểm_H.bổng
A2: Học kỳ 1 Năm học 2023 - 2024 | T2: 0 | U2: < 4.0 | V2: F | W2: 0.0 | X2: 0
B3: Mã Môn học | C3: Tên môn học | D3: Số tín chỉ | E3: Điểm số | F3: Điểm chữ | T3: 4 | U3: 4.0 - 4.9 | V3: D | W3: 1.0 | X3: 1
B4: CO1005 | C4: Nhập môn Điện toán | D4: 3 | E4: 7.4 | F4: B | H4: =IF(D4>0,VLOOKUP(F4,$V$2:$X$10,3,0)*D4,0) -> 9 | I4: =IF(H4>0,D4,0) -> 3 | M4: =IF(L4="ct",0,IF(ISBLANK(L4),H4,VLOOKUP(L4,$T$2:$X$10,5,1)*D4)) -> 9 | N4: =IF(L4="ct",0,I4) -> 3 | T4: 5 | U4: 5.0 - 5.4 | V4: D+ | W4: 1.5 | X4: 1
B5: CO1023 | C5: Hệ thống số | D5: 3 | E5: 6.1 | F5: C | H5: =IF(D5>0,VLOOKUP(F5,$V$2:$X$10,3,0)*D5,0) -> 6 | I5: =IF(H5>0,D5,0) -> 3 | M5: =IF(L5="ct",0,IF(ISBLANK(L5),H5,VLOOKUP(L5,$T$2:$X$10,5,1)*D5)) -> 6 | N5: =IF(L5="ct",0,I5) -> 3 | T5: 5.5 | U5: 5.5 - 6.4 | V5: C | W5: 2.0 | X5: 2
B6: LA1045 | C6: Tiếng Nhật 1 | D6: 0 | E6: 5.4 | F6: D+ | H6: =IF(D6>0,VLOOKUP(F6,$V$2:$X$10,3,0)*D6,0) -> 0 | I6: =IF(H6>0,D6,0) -> 0 | M6: =IF(L6="ct",0,IF(ISBLANK(L6),H6,VLOOKUP(L6,$T$2:$X$10,5,1)*D6)) -> 0 | N6: =IF(L6="ct",0,I6) -> 0 | T6: 6.5 | U6: 6.5 - 6.9 | V6: C+ | W6: 2.5 | X6: 2
B7: MT1003 | C7: Giải tích 1 | D7: 4 | E7: 5.7 | F7: C | H7: =IF(D7>0,VLOOKUP(F7,$V$2:$X$10,3,0)*D7,0) -> 8 | I7: =IF(H7>0,D7,0) -> 4 | M7: =IF(L7="ct",0,IF(ISBLANK(L7),H7,VLOOKUP(L7,$T$2:$X$10,5,1)*D7)) -> 8 | N7: =IF(L7="ct",0,I7) -> 4 | T7: 7 | U7: 7.0 - 7.9 | V7: B | W7: 3.0 | X7: 3
B8: PE1011 | C8: Bóng chuyền (Học phần 1) | D8: 0 | E8: 6.0 | F8: C | H8: =IF(D8>0,VLOOKUP(F8,$V$2:$X$10,3,0)*D8,0) -> 0 | I8: =IF(H8>0,D8,0) -> 0 | M8: =IF(L8="ct",0,IF(ISBLANK(L8),H8,VLOOKUP(L8,$T$2:$X$10,5,1)*D8)) -> 0 | N8: =IF(L8="ct",0,I8) -> 0 | T8: 8 | U8: 8.0 - 8.4 | V8: B+ | W8: 3.5 | X8: 3
B9: PH1003 | C9: Vật lý 1 | D9: 4 | E9: 3.5 | F9: F | H9: =IF(D9>0,VLOOKUP(F9,$V$2:$X$10,3,0)*D9,0) -> 0 | I9: =IF(H9>0,D9,0) -> 0 | M9: =IF(L9="ct",0,IF(ISBLANK(L9),H9,VLOOKUP(L9,$T$2:$X$10,5,1)*D9)) -> 0 | N9: =IF(L9="ct",0,I9) -> 0 | T9: 8.5 | U9: 8.5 - 9.4 | V9: A | W9: 4.0 | X9: 4
B10: SP1041 | C10: Kỹ năng mềm | D10: 0 | E10: 8.3 | F10: B+ | H10: =IF(D10>0,VLOOKUP(F10,$V$2:$X$10,3,0)*D10,0) -> 0 | I10: =IF(H10>0,D10,0) -> 0 | M10: =IF(L10="ct",0,IF(ISBLANK(L10),H10,VLOOKUP(L10,$T$2:$X$10,5,1)*D10)) -> 0 | N10: =IF(L10="ct",0,I10) -> 0 | T10: 9.5 | U10: 9.5 - 10.0 | V10: A+ | W10: 4.0 | X10: 4
B11: SP1045 | C11: Kỹ năng Xã hội I | D11: 0 | E11: 9.2 | F11: A | H11: =IF(D11>0,VLOOKUP(F11,$V$2:$X$10,3,0)*D11,0) -> 0 | I11: =IF(H11>0,D11,0) -> 0 | M11: =IF(L11="ct",0,IF(ISBLANK(L11),H11,VLOOKUP(L11,$T$2:$X$10,5,1)*D11)) -> 0 | N11: =IF(L11="ct",0,I11) -> 0
A12: ĐTBHK: 1.6 | D12: ĐTBTL chung: 1.6 | F12: =SUM(H4:H11)/SUM(D4:D11) -> 1.6428571 | M12: =IF(L12="ct",0,IF(ISBLANK(L12),H12,VLOOKUP(L12,$T$2:$X$10,5,1)*D12)) -> 0 | N12: =IF(L12="ct",0,I12) -> 0
M13: =IF(L13="ct",0,IF(ISBLANK(L13),H13,VLOOKUP(L13,$T$2:$X$10,5,1)*D13)) -> 0 | N13: =IF(L13="ct",0,I13) -> 0 | U13: Xếp loại
A14: Học kỳ 2 Năm học 2023 - 2024 | M14: =IF(L14="ct",0,IF(ISBLANK(L14),H14,VLOOKUP(L14,$T$2:$X$10,5,1)*D14)) -> 0 | N14: =IF(L14="ct",0,I14) -> 0 | U14: 3.6 - 4.0 | V14: Xuất sắc
B15: Mã Môn học | C15: Tên môn học | D15: Số tín chỉ | E15: Điểm số | F15: Điểm chữ | M15: =IF(L15="ct",0,IF(ISBLANK(L15),H15,VLOOKUP(L15,$T$2:$X$10,5,1)*D15)) -> 0 | N15: =IF(L15="ct",0,I15) -> 0 | U15: 3.2 - 3.5 | V15: Giỏi
B16: PE1039 | C16: Bóng rổ (Học phần 2) | D16: 0 | E16: 6.0 | F16: C | H16: =IF(D16>0,VLOOKUP(F16,$V$2:$X$10,3,0)*D16,0) -> 0 | I16: =IF(H16>0,D16,0) -> 0 | M16: =IF(L16="ct",0,IF(ISBLANK(L16),H16,VLOOKUP(L16,$T$2:$X$10,5,1)*D16)) -> 0 | N16: =IF(L16="ct",0,I16) -> 0 | U16: 2.5 - 3.1 | V16: Khá
B17: CO1007 | C17: Cấu trúc Rời rạc cho Khoa học Máy tính | D17: 4 | E17: 4.8 | F17: D | H17: =IF(D17>0,VLOOKUP(F17,$V$2:$X$10,3,0)*D17,0) -> 4 | I17: =IF(H17>0,D17,0) -> 4 | M17: =IF(L17="ct",0,IF(ISBLANK(L17),H17,VLOOKUP(L17,$T$2:$X$10,5,1)*D17)) -> 4 | N17: =IF(L17="ct",0,I17) -> 4 | U17: 2.0 - 2.4 | V17: Trung bình
B18: CO1027 | C18: Kỹ thuật Lập trình | D18: 3 | E18: 6.0 | F18: C | H18: =IF(D18>0,VLOOKUP(F18,$V$2:$X$10,3,0)*D18,0) -> 6 | I18: =IF(H18>0,D18,0) -> 3 | M18: =IF(L18="ct",0,IF(ISBLANK(L18),H18,VLOOKUP(L18,$T$2:$X$10,5,1)*D18)) -> 6 | N18: =IF(L18="ct",0,I18) -> 3 | U18: 1.0 - 1.9 | V18: Yếu
B19: LA1047 | C19: Tiếng Nhật 2 | D19: 0 | E19: 5.0 | F19: D+ | H19: =IF(D19>0,VLOOKUP(F19,$V$2:$X$10,3,0)*D19,0) -> 0 | I19: =IF(H19>0,D19,0) -> 0 | M19: =IF(L19="ct",0,IF(ISBLANK(L19),H19,VLOOKUP(L19,$T$2:$X$10,5,1)*D19)) -> 0 | N19: =IF(L19="ct",0,I19) -> 0 | U19: < 1.0 | V19: Kém
B20: MI1003 | C20: Giáo dục Quốc phòng | D20: 0 | E20: DT | F20: -- | H20: =IF(D20>0,VLOOKUP(F20,$V$2:$X$10,3,0)*D20,0) -> 0 | I20: =IF(H20>0,D20,0) -> 0 | M20: =IF(L20="ct",0,IF(ISBLANK(L20),H20,VLOOKUP(L20,$T$2:$X$10,5,1)*D20)) -> 0 | N20: =IF(L20="ct",0,I20) -> 0
B21: MT1005 | C21: Giải tích 2 | D21: 4 | E21: 3.3 | F21: F | H21: =IF(D21>0,VLOOKUP(F21,$V$2:$X$10,3,0)*D21,0) -> 0 | I21: =IF(H21>0,D21,0) -> 0 | L21: 5.5 | M21: =IF(L21="ct",0,IF(ISBLANK(L21),H21,VLOOKUP(L21,$T$2:$X$10,5,1)*D21)) -> 8 | N21: =IF(L21="ct",0,I21) -> 0
B22: MT1007 | C22: Đại số Tuyến tính | D22: 3 | E22: 4.0 | F22: D | H22: =IF(D22>0,VLOOKUP(F22,$V$2:$X$10,3,0)*D22,0) -> 3 | I22: =IF(H22>0,D22,0) -> 3 | M22: =IF(L22="ct",0,IF(ISBLANK(L22),H22,VLOOKUP(L22,$T$2:$X$10,5,1)*D22)) -> 3 | N22: =IF(L22="ct",0,I22) -> 3
B23: PH1007 | C23: Thí nghiệm Vật lý | D23: 1 | E23: 8.5 | F23: A | H23: =IF(D23>0,VLOOKUP(F23,$V$2:$X$10,3,0)*D23,0) -> 4 | I23: =IF(H23>0,D23,0) -> 1 | M23: =IF(L23="ct",0,IF(ISBLANK(L23),H23,VLOOKUP(L23,$T$2:$X$10,5,1)*D23)) -> 4 | N23: =IF(L23="ct",0,I23) -> 1
A24: ĐTBHK: 1.2 | D24: ĐTBTL chung: 1.4 | F24: =SUM(H16:H23)/SUM(D16:D23) -> 1.1333333 | M24: =IF(L24="ct",0,IF(ISBLANK(L24),H24,VLOOKUP(L24,$T$2:$X$10,5,1)*D24)) -> 0 | N24: =IF(L24="ct",0,I24) -> 0
M25: =IF(L25="ct",0,IF(ISBLANK(L25),H25,VLOOKUP(L25,$T$2:$X$10,5,1)*D25)) -> 0 | N25: =IF(L25="ct",0,I25) -> 0
A26: Học kỳ 3 Năm học 2024 - 2025 | M26: =IF(L26="ct",0,IF(ISBLANK(L26),H26,VLOOKUP(L26,$T$2:$X$10,5,1)*D26)) -> 0 | N26: =IF(L26="ct",0,I26) -> 0
B27: Mã Môn học | C27: Tên môn học | D27: Số tín chỉ | E27: Điểm số | F27: Điểm chữ | M27: =IF(L27="ct",0,IF(ISBLANK(L27),H27,VLOOKUP(L27,$T$2:$X$10,5,1)*D27)) -> 0 | N27: =IF(L27="ct",0,I27) -> 0
B28: MT1005 | C28: Giải tích 2 | D28: 4 | E28: 1.5 | F28: F | H28: =IF(D28>0,VLOOKUP(F28,$V$2:$X$10,3,0)*D28,0) -> 0 | I28: =IF(H28>0,D28,0) -> 0 | M28: =IF(L28="ct",0,IF(ISBLANK(L28),H28,VLOOKUP(L28,$T$2:$X$10,5,1)*D28)) -> 0 | N28: =IF(L28="ct",0,I28) -> 0
B29: MT2013 | C29: Xác suất và Thống kê | D29: 4 | E29: 4.5 | F29: D | H29: =IF(D29>0,VLOOKUP(F29,$V$2:$X$10,3,0)*D29,0) -> 4 | I29: =IF(H29>0,D29,0) -> 4 | M29: =IF(L29="ct",0,IF(ISBLANK(L29),H29,VLOOKUP(L29,$T$2:$X$10,5,1)*D29)) -> 4 | N29: =IF(L29="ct",0,I29) -> 4
B30: SP1031 | C30: Triết học Mác - Lênin | D30: 3 | E30: 6.6 | F30: C+ | H30: =IF(D30>0,VLOOKUP(F30,$V$2:$X$10,3,0)*D30,0) -> 6 | I30: =IF(H30>0,D30,0) -> 3 | M30: =IF(L30="ct",0,IF(ISBLANK(L30),H30,VLOOKUP(L30,$T$2:$X$10,5,1)*D30)) -> 6 | N30: =IF(L30="ct",0,I30) -> 3
A31: ĐTBHK: 1.0 | D31: ĐTBTL chung: 1.5 | M31: =IF(L31="ct",0,IF(ISBLANK(L31),H31,VLOOKUP(L31,$T$2:$X$10,5,1)*D31)) -> 0 | N31: =IF(L31="ct",0,I31) -> 0
M32: =IF(L32="ct",0,IF(ISBLANK(L32),H32,VLOOKUP(L32,$T$2:$X$10,5,1)*D32)) -> 0 | N32: =IF(L32="ct",0,I32) -> 0
A33: Học kỳ 1 Năm học 2024 - 2025 | M33: =IF(L33="ct",0,IF(ISBLANK(L33),H33,VLOOKUP(L33,$T$2:$X$10,5,1)*D33)) -> 0 | N33: =IF(L33="ct",0,I33) -> 0
B34: Mã Môn học | C34: Tên môn học | D34: Số tín chỉ | E34: Điểm số | F34: Điểm chữ | M34: =IF(L34="ct",0,IF(ISBLANK(L34),H34,VLOOKUP(L34,$T$2:$X$10,5,1)*D34)) -> 0 | N34: =IF(L34="ct",0,I34) -> 0
B35: LA2017 | C35: Tiếng Nhật 3 | D35: 0 | E35: 5.9 | F35: C | H35: =IF(D35>0,VLOOKUP(F35,$V$2:$X$10,3,0)*D35,0) -> 0 | I35: =IF(H35>0,D35,0) -> 0 | M35: =IF(L35="ct",0,IF(ISBLANK(L35),H35,VLOOKUP(L35,$T$2:$X$10,5,1)*D35)) -> 0 | N35: =IF(L35="ct",0,I35) -> 0
B36: CO2003 | C36: Cấu trúc Dữ liệu và Giải Thuật | D36: 4 | E36: 3.6 | F36: F | H36: =IF(D36>0,VLOOKUP(F36,$V$2:$X$10,3,0)*D36,0) -> 0 | I36: =IF(H36>0,D36,0) -> 0 | M36: =IF(L36="ct",0,IF(ISBLANK(L36),H36,VLOOKUP(L36,$T$2:$X$10,5,1)*D36)) -> 0 | N36: =IF(L36="ct",0,I36) -> 0
B37: CO2007 | C37: Kiến trúc Máy tính | D37: 4 | E37: 6.1 | F37: C | H37: =IF(D37>0,VLOOKUP(F37,$V$2:$X$10,3,0)*D37,0) -> 8 | I37: =IF(H37>0,D37,0) -> 4 | M37: =IF(L37="ct",0,IF(ISBLANK(L37),H37,VLOOKUP(L37,$T$2:$X$10,5,1)*D37)) -> 8 | N37: =IF(L37="ct",0,I37) -> 4
B38: CO2011 | C38: Mô hình hóa Toán học | D38: 3 | E38: 4.8 | F38: D | H38: =IF(D38>0,VLOOKUP(F38,$V$2:$X$10,3,0)*D38,0) -> 3 | I38: =IF(H38>0,D38,0) -> 3 | M38: =IF(L38="ct",0,IF(ISBLANK(L38),H38,VLOOKUP(L38,$T$2:$X$10,5,1)*D38)) -> 3 | N38: =IF(L38="ct",0,I38) -> 3
B39: PH1003 | C39: Vật lý 1 | D39: 4 | E39: 5.9 | F39: C | H39: =IF(D39>0,VLOOKUP(F39,$V$2:$X$10,3,0)*D39,0) -> 8 | I39: =IF(H39>0,D39,0) -> 4 | M39: =IF(L39="ct",0,IF(ISBLANK(L39),H39,VLOOKUP(L39,$T$2:$X$10,5,1)*D39)) -> 8 | N39: =IF(L39="ct",0,I39) -> 4
A40: ĐTBHK: 1.0 | D40: ĐTBTL chung: 1.5
...

Sheet Sheet1
K1: TCTL-chung | L1: TCTL-hk
B2: Mã môn học | C2: Tên môn học | D2: Tín chỉ | E2: Nhóm | F2: Điểm số | G2: Điểm chữ | H2: Điểm đạt | I2: tc-dat | J2: diemso | K2: =SUM(K3:K40)/SUM(I3:I40) -> 1.6311475 | P2: tc-dat_xtn | Q2: ttich | R2: =SUM(Q3:Q31)/SUM(#REF!) -> #REF!
A3: 231 | B3: CO1005 | C3: Nhập môn Điện toán | D3: 3 | E3: CN01 | F3: 7.4 | G3: B | I3: =D3 -> 3 | J3: =VLOOKUP(VALUE(CONCATENATE(LEFT(F3,1),",",RIGHT(F3))),'KQ-hoctap'!$T$2:$X$10,4,1) -> 3.0 | K3: =IF(ISBLANK(J3),0,VALUE(CONCATENATE(LEFT(J3,1),",",RIGHT(J3,1))))*I3 -> 9 | P3: =#REF! -> #REF! | Q3: =VALUE(CONCATENATE(LEFT(J3,1),",",RIGHT(J3,1)))*#REF! -> #REF!
A4: 231 | B4: CO1023 | C4: Hệ thống số | D4: 3 | E4: CN01 | F4: 6.1 | G4: C | I4: =D4 -> 3 | J4: =VLOOKUP(VALUE(CONCATENATE(LEFT(F4,1),",",RIGHT(F4))),'KQ-hoctap'!$T$2:$X$10,4,1) -> 2.0 | K4: =IF(ISBLANK(J4),0,VALUE(CONCATENATE(LEFT(J4,1),",",RIGHT(J4,1))))*I4 -> 6 | P4: =#REF! -> #REF! | Q4: =VALUE(CONCATENATE(LEFT(J4,1),",",RIGHT(J4,1)))*#REF! -> #REF!
A5: 231 | B5: LA1045 | C5: Tiếng Nhật 1 | D5: 0 | E5: CN01 | F5: 5.4 | G5: D+
A6: 231 | B6: MT1003 | C6: Giải tích 1 | D6: 4 | E6: CN02 | F6: 5.7 | G6: C | I6: =D6 -> 4 | J6: =VLOOKUP(VALUE(CONCATENATE(LEFT(F6,1),",",RIGHT(F6))),'KQ-hoctap'!$T$2:$X$10,4,1) -> 2.0 | K6: =IF(ISBLANK(J6),0,VALUE(CONCATENATE(LEFT(J6,1),",",RIGHT(J6,1))))*I6 -> 8 | P6: =#REF! -> #REF! | Q6: =VALUE(CONCATENATE(LEFT(J6,1),",",RIGHT(J6,1)))*#REF! -> #REF!
A7: 231 | B7: PE1011 | C7: Bóng chuyền (Học phần 1) | D7: 0 | E7: CC06 | F7: 6.0 | G7: C
A8: 231 | B8: PH1003 | C8: Vật lý 1 | D8: 4 | E8: CN02 | F8: 3.5 | G8: F | H8: -- | I8: =D8 -> 4 | K8: =IF(ISBLANK(J8),0,VALUE(CONCATENATE(LEFT(J8,1),",",RIGHT(J8,1))))*I8 -> 0
A9: 231 | B9: SP1041 | C9: Kỹ năng mềm | D9: 0 | E9: CN03 | F9: 8.3 | G9: B+
A10: 231 | B10: SP1045 | C10: Kỹ năng Xã hội I | D10: 0 | E10: CC03 | F10: 9.2 | G10: A
A11: 231* | B11: ĐTBHK: 1.6 | C11: ĐTBTL chung: 1.6 | L11: =SUM(K3:K10)/SUM(I3:I10) -> 1.6428571 | R11: =SUM(Q3:Q10)/SUM(#REF!) -> #REF!
A12: 232 | B12: CO1007 | C12: Cấu trúc Rời rạc cho Khoa học Máy tính | D12: 4 | E12: CN01 | F12: 5.0 | G12: D+ | I12: =D12 -> 4 | J12: =VLOOKUP(VALUE(CONCATENATE(LEFT(F12,1),",",RIGHT(F12))),'KQ-hoctap'!$T$2:$X$10,4,1) -> 1.5 | K12: =IF(ISBLANK(J12),0,VALUE(CONCATENATE(LEFT(J12,1),",",RIGHT(J12,1))))*I12 -> 6 | P12: =#REF! -> #REF! | Q12: =VALUE(CONCATENATE(LEFT(J12,1),",",RIGHT(J12,1)))*#REF! -> #REF!
A13: 232 | B13: CO1027 | C13: Kỹ thuật Lập trình | D13: 3 | E13: CN01 | F13: 6.0 | G13: C | I13: =D13 -> 3 | J13: =VLOOKUP(VALUE(CONCATENATE(LEFT(F13,1),",",RIGHT(F13))),'KQ-hoctap'!$T$2:$X$10,4,1) -> 2.0 | K13: =IF(ISBLANK(J13),0,VALUE(CONCATENATE(LEFT(J13,1),",",RIGHT(J13,1))))*I13 -> 6 | P13: =#REF! -> #REF! | Q13: =VALUE(CONCATENATE(LEFT(J13,1),",",RIGHT(J13,1)))*#REF! -> #REF!
A14: 232 | B14: LA1047 | C14: Tiếng Nhật 2 | D14: 0 | E14: CN02 | F14: 5.0 | G14: D+
A15: 232 | B15: MI1003 | C15: Giáo dục Quốc phòng | D15: 0 | E15: A02 | F15: DT | G15: --
A16: 232 | B16: MT1005 | C16: Giải tích 2 | D16: 4 | E16: CN02 | F16: 3.3 | G16: F | H16: -- | K16: =IF(ISBLANK(J16),0,VALUE(CONCATENATE(LEFT(J16,1),",",RIGHT(J16,1))))*I16 -> 0
A17: 232 | B17: MT1007 | C17: Đại số Tuyến tính | D17: 3 | E17: CN02 | F17: 4.0 | G17: D | I17: =D17 -> 3 | J17: =VLOOKUP(VALUE(CONCATENATE(LEFT(F17,1),",",RIGHT(F17))),'KQ-hoctap'!$T$2:$X$10,4,1) -> 1.0 | K17: =IF(ISBLANK(J17),0,VALUE(CONCATENATE(LEFT(J17,1),",",RIGHT(J17,1))))*I17 -> 3 | P17: =#REF! -> #REF! | Q17: =VALUE(CONCATENATE(LEFT(J17,1),",",RIGHT(J17,1)))*#REF! -> #REF!
A18: 232 | B18: PE1039 | C18: Bóng rổ (Học phần 2) | D18: 0 | E18: CC06 | F18: 6.0 | G18: C
A19: 232 | B19: PH1007 | C19: Thí nghiệm Vật lý | D19: 1 | E19: CN07 | F19: 8.5 | G19: A | I19: =D19 -> 1 | J19: =VLOOKUP(VALUE(CONCATENATE(LEFT(F19,1),",",RIGHT(F19))),'KQ-hoctap'!$T$2:$X$10,4,1) -> 4.0 | K19: =IF(ISBLANK(J19),0,VALUE(CONCATENATE(LEFT(J19,1),",",RIGHT(J19,1))))*I19 -> 4 | P19: =#REF! -> #REF! | Q19: =VALUE(CONCATENATE(LEFT(J19,1),",",RIGHT(J19,1)))*#REF! -> #REF!
A20: 232* | B20: ĐTBHK: 1.3 | C20: ĐTBTL chung: 1.4 | L20: =SUM(K12:K19)/SUM(I12:I19) -> 1.7272727
A21: 233 | B21: MT1005 | C21: Giải tích 2 | D21: 4 | E21: DT01 | F21: 1.5 | G21: F | H21: --
A22: 233 | B22: MT2013 | C22: Xác suất và Thống kê | D22: 4 | E22: DT02 | F22: 4.5 | G22: D | I22: =D22 -> 4 | J22: =VLOOKUP(VALUE(CONCATENATE(LEFT(F22,1),",",RIGHT(F22))),'KQ-hoctap'!$T$2:$X$10,4,1) -> 1.0 | K22: =IF(ISBLANK(J22),0,VALUE(CONCATENATE(LEFT(J22,1),",",RIGHT(J22,1))))*I22 -> 4 | P22: =#REF! -> #REF! | Q22: =VALUE(CONCATENATE(LEFT(J22,1),",",RIGHT(J22,1)))*#REF! -> #REF!
A23: 233 | B23: SP1031 | C23: Triết học Mác - Lênin | D23: 3 | E23: DT01 | F23: 6.6 | G23: C+ | I23: =D23 -> 3 | J23: =VLOOKUP(VALUE(CONCATENATE(LEFT(F23,1),",",RIGHT(F23))),'KQ-hoctap'!$T$2:$X$10,4,1) -> 2.5 | K23: =IF(ISBLANK(J23),0,VALUE(CONCATENATE(LEFT(J23,1),",",RIGHT(J23,1))))*I23 -> 7.5 | P23: =#REF! -> #REF! | Q23: =VALUE(CONCATENATE(LEFT(J23,1),",",RIGHT(J23,1)))*#REF! -> #REF!
A24: 233* | B24: ĐTBHK: 1.0 | C24: ĐTBTL chung: 1.5 | L24: =SUM(I21:I23)/SUM(K21:K23) -> 0.60869565
A25: 241 | B25: CO2003 | C25: Cấu trúc Dữ liệu và Giải Thuật | D25: 4 | E25: CN02 | F25: 3.6 | G25: F | H25: -- | I25: =D25 -> 4 | K25: =IF(ISBLANK(J25),0,VALUE(CONCATENATE(LEFT(J25,1),",",RIGHT(J25,1))))*I25 -> 0
A26: 241 | B26: CO2007 | C26: Kiến trúc Máy tính | D26: 4 | E26: CN02 | F26: 6.1 | G26: C | I26: =D26 -> 4 | J26: =VLOOKUP(VALUE(CONCATENATE(LEFT(F26,1),",",RIGHT(F26))),'KQ-hoctap'!$T$2:$X$10,4,1) -> 2.0 | K26: =IF(ISBLANK(J26),0,VALUE(CONCATENATE(LEFT(J26,1),",",RIGHT(J26,1))))*I26 -> 8 | P26: =#REF! -> #REF! | Q26: =VALUE(CONCATENATE(LEFT(J26,1),",",RIGHT(J26,1)))*#REF! -> #REF!
A27: 241 | B27: CO2011 | C27: Mô hình hóa Toán học | D27: 3 | E27: CN01 | F27: 4.8 | G27: D | I27: =D27 -> 3 | J27: =VLOOKUP(VALUE(CONCATENATE(LEFT(F27,1),",",RIGHT(F27))),'KQ-hoctap'!$T$2:$X$10,4,1) -> 1.0 | K27: =IF(ISBLANK(J27),0,VALUE(CONCATENATE(LEFT(J27,1),",",RIGHT(J27,1))))*I27 -> 3 | P27: =#REF! -> #REF! | Q27: =VALUE(CONCATENATE(LEFT(J27,1),",",RIGHT(J27,1)))*#REF! -> #REF!
A28: 241 | B28: LA2017 | C28: Tiếng Nhật 3 | D28: 0 | E28: CN02 | F28: 5.9 | G28: C
A29: 241 | B29: PH1003 | C29: Vật lý 1 | D29: 4 | E29: CN01 | F29: 5.9 | G29: C | I29: =D29 -> 4 | J29: =VLOOKUP(VALUE(CONCATENATE(LEFT(F29,1),",",RIGHT(F29))),'KQ-hoctap'!$T$2:$X$10,4,1) -> 2.0 | K29: =IF(ISBLANK(J29),0,VALUE(CONCATENATE(LEFT(J29,1),",",RIGHT(J29,1))))*I29 -> 8 | P29: =#REF! -> #REF! | Q29: =VALUE(CONCATENATE(LEFT(J29,1),",",RIGHT(J29,1)))*#REF! -> #REF!
A30: 241* | B30: ĐTBHK: 1.3 | C30: ĐTBTL chung: 1.5 | L30: =SUM(K25:K29)/SUM(I25:I29) -> 1.2666667
A31: 242 | B31: LA2019 | C31: Tiếng Nhật 4 | D31: 0
A32: 242 | B32: CO2017 | C32: Hệ điều hành | D32: 3 | F32: 5.0 | I32: =D32 -> 3 | J32: =VLOOKUP(VALUE(CONCATENATE(LEFT(F32,1),",",RIGHT(F32))),'KQ-hoctap'!$T$2:$X$10,4,1) -> 1.5 | K32: =IF(ISBLANK(J32),0,VALUE(CONCATENATE(LEFT(J32,1),",",RIGHT(J32,1))))*I32 -> 4.5 | P32: =#REF! -> #REF!
A33: 242 | B33: CO2039 | C33: Lập trình Nâng cao | D33: 3 | F33: 5.0 | I33: =D33 -> 3 | J33: =VLOOKUP(VALUE(CONCATENATE(LEFT(F33,1),",",RIGHT(F33))),'KQ-hoctap'!$T$2:$X$10,4,1) -> 1.5 | K33: =IF(ISBLANK(J33),0,VALUE(CONCATENATE(LEFT(J33,1),",",RIGHT(J33,1))))*I33 -> 4.5 | P33: =#REF! -> #REF!
A34: 242 | B34: MT1005 | C34: Giải tích 2 | D34: 4 | F34: 5.5 | I34: =D34 -> 4 | J34: =VLOOKUP(VALUE(CONCATENATE(LEFT(F34,1),",",RIGHT(F34))),'KQ-hoctap'!$T$2:$X$10,4,1) -> 2.0 | K34: =IF(ISBLANK(J34),0,VALUE(CONCATENATE(LEFT(J34,1),",",RIGHT(J34,1))))*I34 -> 8 | P34: =#REF! -> #REF!
A35: 242 | B35: SP1007 | C35: Pháp luật Việt Nam Đại cương | D35: 2 | F35: 6.5 | I35: =D35 -> 2 | J35: =VLOOKUP(VALUE(CONCATENATE(LEFT(F35,1),",",RIGHT(F35))),'KQ-hoctap'!$T$2:$X$10,4,1) -> 2.5 | K35: =IF(ISBLANK(J35),0,VALUE(CONCATENATE(LEFT(J35,1),",",RIGHT(J35,1))))*I35 -> 5 | P35: =#REF! -> #REF!
A36: 242 | B36: SP1033 | C36: Kinh tế Chính trị Mác - Lênin | D36: 2 | F36: 6.5 | I36: =D36 -> 2 | J36: =VLOOKUP(VALUE(CONCATENATE(LEFT(F36,1),",",RIGHT(F36))),'KQ-hoctap'!$T$2:$X$10,4,1) -> 2.5 | K36: =IF(ISBLANK(J36),0,VALUE(CONCATENATE(LEFT(J36,1),",",RIGHT(J36,1))))*I36 -> 5 | P36: =#REF! -> #REF!
A37: 242*
